Traceback (most recent call last):
  File "/home/robotics20/anaconda3/envs/rotem/lib/python3.10/site-packages/pandas/core/indexes/base.py", line 3802, in get_loc
    return self._engine.get_loc(casted_key)
  File "pandas/_libs/index.pyx", line 138, in pandas._libs.index.IndexEngine.get_loc
  File "pandas/_libs/index.pyx", line 165, in pandas._libs.index.IndexEngine.get_loc
  File "pandas/_libs/hashtable_class_helper.pxi", line 5745, in pandas._libs.hashtable.PyObjectHashTable.get_item
  File "pandas/_libs/hashtable_class_helper.pxi", line 5753, in pandas._libs.hashtable.PyObjectHashTable.get_item
KeyError: '1'
The above exception was the direct cause of the following exception:
Traceback (most recent call last):
  File "/home/robotics20/anaconda3/envs/rotem/lib/python3.10/site-packages/pandas/core/indexes/base.py", line 3804, in get_loc
    raise KeyError(key) from err
KeyError: '1'